Exception in thread Thread-4:
Traceback (most recent call last):
  File "C:\Users\Zaviel\anaconda3\envs\v5\lib\threading.py", line 926, in _bootstrap_inner
    self.run()
  File "C:\Users\Zaviel\anaconda3\envs\v5\lib\threading.py", line 870, in run
    self._target(*self._args, **self._kwargs)
  File "with_method.py", line 75, in release_response
    globals()[evt].clear()
KeyError: 'evt'




            release_key = ""
            if len(r_list):
                for x in r_list:
                    if x in press_repeat:
                        release_key = x
                        break
                if release_key!="":
                    evt = release_key.replace("'","") + "evt"
                    globals()[evt].clear()
                    #press_list.remove(release_key.replace("'",""))
                    press_repeat.remove(release_key.replace("'",""))
                    r_list.remove(release_key.replace("'",""))